{"trial_id": "0000", "hyperparameters": {"space": [{"class_name": "Choice", "config": {"name": "activation", "default": "relu", "conditions": [], "values": ["relu", "tanh"], "ordered": false}}, {"class_name": "Int", "config": {"name": "first_units", "default": null, "conditions": [], "min_value": 1, "max_value": 30, "step": 5, "sampling": "linear"}}, {"class_name": "Int", "config": {"name": "num_layers", "default": null, "conditions": [], "min_value": 1, "max_value": 5, "step": 1, "sampling": "linear"}}, {"class_name": "Int", "config": {"name": "units_0", "default": null, "conditions": [], "min_value": 1, "max_value": 30, "step": 5, "sampling": "linear"}}], "values": {"activation": "tanh", "first_units": 6, "num_layers": 1, "units_0": 21, "tuner/epochs": 3, "tuner/initial_epoch": 0, "tuner/bracket": 2, "tuner/round": 0}}, "metrics": {"metrics": {}}, "score": null, "best_step": 0, "status": "FAILED", "message": "Traceback (most recent call last):\n  File \"/Users/joshuasamuel/opt/anaconda3/lib/python3.9/site-packages/keras_tuner/engine/base_tuner.py\", line 250, in _try_run_and_update_trial\n    self._run_and_update_trial(trial, *fit_args, **fit_kwargs)\n  File \"/Users/joshuasamuel/opt/anaconda3/lib/python3.9/site-packages/keras_tuner/engine/base_tuner.py\", line 215, in _run_and_update_trial\n    results = self.run_trial(trial, *fit_args, **fit_kwargs)\n  File \"/Users/joshuasamuel/opt/anaconda3/lib/python3.9/site-packages/keras_tuner/tuners/hyperband.py\", line 404, in run_trial\n    return super().run_trial(trial, *fit_args, **fit_kwargs)\n  File \"/Users/joshuasamuel/opt/anaconda3/lib/python3.9/site-packages/keras_tuner/engine/tuner.py\", line 286, in run_trial\n    obj_value = self._build_and_fit_model(trial, *args, **copied_kwargs)\n  File \"/Users/joshuasamuel/opt/anaconda3/lib/python3.9/site-packages/keras_tuner/engine/tuner.py\", line 213, in _build_and_fit_model\n    results = self.hypermodel.fit(hp, model, *args, **kwargs)\n  File \"/Users/joshuasamuel/opt/anaconda3/lib/python3.9/site-packages/keras_tuner/engine/hypermodel.py\", line 144, in fit\n    return model.fit(*args, **kwargs)\n  File \"/Users/joshuasamuel/opt/anaconda3/lib/python3.9/site-packages/keras/utils/traceback_utils.py\", line 70, in error_handler\n    raise e.with_traceback(filtered_tb) from None\n  File \"/var/folders/sn/80v6hjfx48j1__621jw8jgfm0000gn/T/__autograph_generated_file1chqq4c6.py\", line 15, in tf__train_function\n    retval_ = ag__.converted_call(ag__.ld(step_function), (ag__.ld(self), ag__.ld(iterator)), None, fscope)\nValueError: in user code:\n\n    File \"/Users/joshuasamuel/opt/anaconda3/lib/python3.9/site-packages/keras/engine/training.py\", line 1249, in train_function  *\n        return step_function(self, iterator)\n    File \"/Users/joshuasamuel/opt/anaconda3/lib/python3.9/site-packages/keras/engine/training.py\", line 1233, in step_function  **\n        outputs = model.distribute_strategy.run(run_step, args=(data,))\n    File \"/Users/joshuasamuel/opt/anaconda3/lib/python3.9/site-packages/keras/engine/training.py\", line 1222, in run_step  **\n        outputs = model.train_step(data)\n    File \"/Users/joshuasamuel/opt/anaconda3/lib/python3.9/site-packages/keras/engine/training.py\", line 1023, in train_step\n        y_pred = self(x, training=True)\n    File \"/Users/joshuasamuel/opt/anaconda3/lib/python3.9/site-packages/keras/utils/traceback_utils.py\", line 70, in error_handler\n        raise e.with_traceback(filtered_tb) from None\n    File \"/Users/joshuasamuel/opt/anaconda3/lib/python3.9/site-packages/keras/engine/input_spec.py\", line 295, in assert_input_compatibility\n        raise ValueError(\n\n    ValueError: Input 0 of layer \"sequential\" is incompatible with the layer: expected shape=(None, 2), found shape=(None, 44)\n\n"}